Traceback (most recent call last):
  File "/opt/homebrew/Caskroom/miniconda/base/envs/jupyterbook/lib/python3.11/site-packages/jupyter_cache/executors/utils.py", line 58, in single_nb_execution
    executenb(
  File "/opt/homebrew/Caskroom/miniconda/base/envs/jupyterbook/lib/python3.11/site-packages/nbclient/client.py", line 1204, in execute
    return NotebookClient(nb=nb, resources=resources, km=km, **kwargs).execute()
           ^^^^^^^^^^^^^^^^^^^^^^^^^^^^^^^^^^^^^^^^^^^^^^^^^^^^^^^^^^^^^^^^^^^^^
  File "/opt/homebrew/Caskroom/miniconda/base/envs/jupyterbook/lib/python3.11/site-packages/nbclient/util.py", line 84, in wrapped
    return just_run(coro(*args, **kwargs))
           ^^^^^^^^^^^^^^^^^^^^^^^^^^^^^^^
  File "/opt/homebrew/Caskroom/miniconda/base/envs/jupyterbook/lib/python3.11/site-packages/nbclient/util.py", line 62, in just_run
    return loop.run_until_complete(coro)
           ^^^^^^^^^^^^^^^^^^^^^^^^^^^^^
  File "/opt/homebrew/Caskroom/miniconda/base/envs/jupyterbook/lib/python3.11/asyncio/base_events.py", line 653, in run_until_complete
    return future.result()
           ^^^^^^^^^^^^^^^
  File "/opt/homebrew/Caskroom/miniconda/base/envs/jupyterbook/lib/python3.11/site-packages/nbclient/client.py", line 663, in async_execute
    await self.async_execute_cell(
  File "/opt/homebrew/Caskroom/miniconda/base/envs/jupyterbook/lib/python3.11/site-packages/nbclient/client.py", line 965, in async_execute_cell
    await self._check_raise_for_error(cell, cell_index, exec_reply)
  File "/opt/homebrew/Caskroom/miniconda/base/envs/jupyterbook/lib/python3.11/site-packages/nbclient/client.py", line 862, in _check_raise_for_error
    raise CellExecutionError.from_cell_and_msg(cell, exec_reply_content)
nbclient.exceptions.CellExecutionError: An error occurred while executing the following cell:
------------------
# Plot the Iris dataset using Plotly
g1 = px.scatter_3d(df,
                   x="sepal_width",
                   y="sepal_length",
                   z="petal_width",
                   color="species",
                   size="petal_length",
                   opacity=0.6,
                   size_max=30,
                   height=700)
g1
------------------

[0;31m---------------------------------------------------------------------------[0m
[0;31mNameError[0m                                 Traceback (most recent call last)
Cell [0;32mIn[3], line 2[0m
[1;32m      1[0m [38;5;66;03m# Plot the Iris dataset using Plotly[39;00m
[0;32m----> 2[0m g1 [38;5;241m=[39m px[38;5;241m.[39mscatter_3d(df,
[1;32m      3[0m                    x[38;5;241m=[39m[38;5;124m"[39m[38;5;124msepal_width[39m[38;5;124m"[39m,
[1;32m      4[0m                    y[38;5;241m=[39m[38;5;124m"[39m[38;5;124msepal_length[39m[38;5;124m"[39m,
[1;32m      5[0m                    z[38;5;241m=[39m[38;5;124m"[39m[38;5;124mpetal_width[39m[38;5;124m"[39m,
[1;32m      6[0m                    color[38;5;241m=[39m[38;5;124m"[39m[38;5;124mspecies[39m[38;5;124m"[39m,
[1;32m      7[0m                    size[38;5;241m=[39m[38;5;124m"[39m[38;5;124mpetal_length[39m[38;5;124m"[39m,
[1;32m      8[0m                    opacity[38;5;241m=[39m[38;5;241m0.6[39m,
[1;32m      9[0m                    size_max[38;5;241m=[39m[38;5;241m30[39m,
[1;32m     10[0m                    height[38;5;241m=[39m[38;5;241m700[39m)
[1;32m     11[0m g1

[0;31mNameError[0m: name 'df' is not defined
NameError: name 'df' is not defined

